### C# Tutorial: Exception Handling with Multiple `catch` Blocks and `finally`

In this tutorial, we'll break down the code you provided and explain how to use multiple `catch` blocks to handle different exceptions and use a `finally` block for cleanup.

### Code Overview:

The program reads an index from the user, uses that index to access an array of numbers, and attempts to perform a division operation. Several exceptions are caught during the execution, and the program handles each one accordingly.

### Code Breakdown:

```csharp
using static System.Runtime.InteropServices.JavaScript.JSType;

int[] numbers = { 107, 33, 44, 96, 85 };

// Throwing a general exception to test exception handling
throw new Exception("Please Try Another Number");

try
{
    int x = Convert.ToInt32(Console.ReadLine()); // Read user input and convert to integer
    Console.WriteLine(numbers[x]); // Access the array using the index provided by the user

    if (x == 0) // If index is 0, throw a custom exception
    {
        throw new Exception("Please Try Another Number");
    }

    int y = 70 / x; // Division operation which can throw DivideByZeroException
}
catch (FormatException ex)
{
    // Handle invalid number format (e.g., user enters a non-numeric value)
    Console.WriteLine(ex.Message + "\t Please Enter A Number");
}
catch (IndexOutOfRangeException ex)
{
    // Handle index out of range (e.g., user enters an index greater than array length)
    Console.WriteLine(ex.Message + "\t Index Must be Less than {0}", numbers.Length);
}
catch (DivideByZeroException ex)
{
    // Handle division by zero error
    Console.WriteLine(ex.Message);
}
catch (Exception ex)
{
    // Catch any other general exception
    Console.WriteLine(ex.Message);
}
finally
{
    // Code that always runs, regardless of whether an exception was thrown
    Console.WriteLine("Program Complete");
}
```

### Explanation:

1. **`try` Block**:

   - The `try` block contains code that may throw exceptions.
   - The program reads user input, converts it to an integer, and uses it to access an array element (`numbers[x]`).
   - It also performs a division operation (`70 / x`), which may cause a `DivideByZeroException` if the user enters 0.

2. **Multiple `catch` Blocks**:
   - **`FormatException`**: This exception occurs if the user enters something that cannot be converted to an integer (e.g., a letter or symbol). The `catch` block handles this case and displays a message prompting the user to enter a number.
   - **`IndexOutOfRangeException`**: If the user enters an index that is outside the valid range of the array (i.e., greater than or equal to the length of the `numbers` array), this exception is caught, and a message indicating the valid range is shown.
   - **`DivideByZeroException`**: If the user enters `0`, a division by zero will occur. This exception is caught, and an appropriate message is displayed.
   - **General `Exception`**: This catches any other exceptions that were not handled by the previous blocks. It is a catch-all for any unexpected issues.
3. **`finally` Block**:
   - The `finally` block is executed regardless of whether an exception was thrown or not. It is used to perform any cleanup actions or display messages indicating that the program has completed its execution.

### Key Concepts:

- **Exception Handling**: The `try-catch` mechanism allows you to handle errors gracefully without crashing the program. Each `catch` block handles a specific type of exception, and the `finally` block is used for code that should always run.
- **Multiple `catch` Blocks**: You can use multiple `catch` blocks to handle different exceptions separately, making the error-handling logic more specific and informative.
- **`finally` Block**: This block ensures that certain code (e.g., cleanup tasks) is executed no matter what, even if an exception occurs.

### Expected Output:

- If the user enters a valid index within the bounds of the array and a non-zero value, the program will display the corresponding number from the array.
- If the user enters invalid data (like non-numeric input), the program will prompt the user to enter a valid number.
- If the user enters an out-of-range index, the program will display a message informing them of the valid range.
- If the user enters 0, the program will handle the division by zero error.

Finally, after all operations (including handling exceptions), the program will print "Program Complete" because the `finally` block is executed at the end.

This example demonstrates how you can use multiple types of exceptions in C# and ensures the program remains robust even in the face of errors.
